Workbook

Sheet Inputs
A1: Company Overview | D1: Cap Table | G1: Seed Round Proposal
D2: Owner | E2: Dilution
A3: Sector | B3: Fintech – SME Payments Infrastructure | D3: Founders | E3: 0.72 | G3: Raise | H3: 3000000
A4: Operating countries | B4: Kenya, Ghana, Côte d’Ivoire | D4: Employees (ESOP) | E4: 0.1 | G4: Pre-money valuation | H4: 12000000
A5: Funding Goal | B5: Seed round of 3M | D5: Friends & Family Investors | E5: 0.15
A6: Target Audience | B6: SMEs in Africa seeking simple, integrated digital payment solutions. | D6: Advisors | E6: 0.03
A8: Financial & Operational Data (USD) | D8: Traction Metrics (Commercial and Financial Performance) | G8: Exit Scenarios / IRR Calculation
A10: Month | B10: Revenue | D10: Metric | E10: Value | G10: Projected Exit in 7 Years
A11: 1 | B11: 21000 | D11: Active SME Clients | E11: 5100
A12: 2 | B12: 26000 | D12: Average Monthly Churn | E12: 0.029 | G12: Scenario | H12: Exit Value | I12: VC Ownership
A13: 3 | B13: 31000 | D13: ARPA (Average Revenue per Account) | E13: 63 | G13: Base Scenario | H13: 120000000 | I13: 0.125
A14: 4 | B14: 35000 | D14: Average Transaction Ticket | E14: 18 | G14: Pessimistic | H14: 45000000 | I14: 0.125
A15: 5 | B15: 43000 | D15: Total Payment Volume (TPV) (Last 12 months) | E15: 174000000 | G15: Optimistic | H15: 300000000 | I15: 0.125
A16: 6 | B16: 50000 | D16: Take Rate | E16: 0.0045
A17: 7 | B17: 62000
A18: 8 | B18: 71000 | G18: Cohort Data
A19: 9 | B19: 88000 | D19: Costs and Financial Health | G19: Month | H19: Amount
A20: 10 | B20: 94000 | D20: Metric | E20: Value | G20: 1 | H20: 1000
A21: 11 | B21: 102000 | D21: Customer Acquisition Cost (CAC) | E21: 52 | G21: 2 | H21: 975
A22: 12 | B22: 118000 | D22: Contribution Margin per Customer | E22: 8.5 | G22: 3 | H22: 960
A23: 13 | B23: 132000 | D23: Average Gross Margin | E23: 0.72 | G23: 4 | H23: 947
A24: 14 | B24: 145000 | D24: Current Monthly Burn | E24: 165000 | G24: 5 | H24: 932
A25: 15 | B25: 160000 | D25: Cash Available | E25: 2100000 | G25: 6 | H25: 915
A26: 16 | B26: 174000 | D26: Runway | E26: =E25/E24 -> 12.727273 | G26: 7 | H26: 902
A27: 17 | B27: 195000 | G27: 8 | H27: 885
A28: 18 | B28: 210000 | D28: Team | G28: 9 | H28: 870
A29: 19 | B29: 223000 | D29: CEO: ex-Flutterwave | G29: 10 | H29: 852
A30: 20 | B30: 240000 | D30: CTO: ex-MFS Africa | G30: 11 | H30: 838
A31: 21 | B31: 263000 | D31: Head of Sales: ex-JumiaPay | G31: 12 | H31: 820
A32: 22 | B32: 281000 | D32: Strong team with relevant African fintech experience – VC-friendly.
A33: 23 | B33: 302000 | D33: Market Data
A34: 24 | B34: 325000 | D34: Digitizable SMEs in Anglophone + Francophone Africa | E34: 18000000
D35: SMEs already digitized | E35: 3200000
D36: Average annual spend on fintech tools per SME | E36: 132

Sheet Analysis
A2: Unit Economics
A3: Metrics | B3: Actual Scenario | C3: Alternative scenario
A4: Churn | B4: =Inputs!E12 -> 0.029 | C4: =F5 -> 0.018
A5: LT | B5: =1/B4 -> 34.482759 | C5: =1/C4 -> 55.555556 | E5: Alternative churn for analysis | F5: 0.018
A6: LTV | B6: =Inputs!E13*Inputs!E23*Analysis!B5 -> 1564.1379 | C6: =Inputs!E13*Inputs!E23*Analysis!C5 -> 2520
A7: LTV/CAC | B7: =B6/Inputs!E21 -> 30.079576 | C7: =C6/Inputs!E21 -> 48.461538
A8: Payback period | B8: =B7/(Inputs!E13*Inputs!E23) -> 0.66312997 | C8: =C7/(Inputs!E13*Inputs!E23) -> 1.0683761
A11: Cohort Analysis (Last 12 month) | E11: Cap Table
A12: Month | B12: Clients | C12: Retention | E12: Esop refresh | F12: 5% pre-money
A13: M1 | B13: 1000 | C13: 1 | E13: Round | F13: Seed
A14: M2 | B14: 975 | C14: =100%-(($B$13-B14)/$B$13) -> 0.975 | E14: ="Series "&F13&" Invested Capital ($M)" -> Series Seed Invested Capital ($M) | F14: 3000000
A15: M3 | B15: 960 | C15: =100%-(($B$14-B15)/$B$14) -> 0.98461538 | E15: Ownership Acquired by New Investors | F15: =F14/F17 -> 0.2
A16: M4 | B16: 947 | C16: =100%-(($B$15-B16)/$B$15) -> 0.98645833 | E16: Pre-Money Valuation ($M) | F16: =12000000 -> 12000000
A17: M5 | B17: 932 | C17: =100%-(($B$16-B17)/$B$16) -> 0.98416051 | E17: Post-Money Valuation ($M) | F17: =F14+F16 -> 15000000
A18: M6 | B18: 915 | C18: =100%-(($B$17-B18)/$B$17) -> 0.98175966
A19: M7 | B19: 902 | C19: =100%-(($B$18-B19)/$B$18) -> 0.98579235 | E19: Investor | F19: Pre seed Ownership | G19: New ownership
A20: M8 | B20: 885 | C20: =100%-(($B$19-B20)/$B$19) -> 0.98115299 | E20: Founders | F20: 0.72 | G20: =((Tableau8[[#This Row],[Pre seed Ownership]])*(1-5%))*(1-$F$15) -> 0.5472
A21: M9 | B21: 870 | C21: =100%-(($B$20-B21)/$B$20) -> 0.98305085 | E21: Employees (ESOP) | F21: 0.1 | G21: =((Tableau8[[#This Row],[Pre seed Ownership]])*(1-5%))*(1-$F$15) -> 0.076
A22: M10 | B22: 852 | C22: =100%-(($B$21-B22)/$B$21) -> 0.97931034 | E22: Friends & Family Investors | F22: 0.15 | G22: =((Tableau8[[#This Row],[Pre seed Ownership]])*(1-5%))*(1-$F$15) -> 0.114
A23: M11 | B23: 838 | C23: =100%-(($B$22-B23)/$B$22) -> 0.98356808 | E23: Advisors | F23: 0.03 | G23: =((Tableau8[[#This Row],[Pre seed Ownership]])*(1-5%))*(1-$F$15) -> 0.0228
A24: M12 | B24: 820 | C24: =100%-(($B$23-B24)/$B$23) -> 0.97852029 | E24: Seed | G24: 0.2
E25: Esop refressh | G25: =5%*(1-20%) -> 0.04
E26: Total | F26: =SUM(F20:F23) -> 1 | G26: =SUM(G20:G25) -> 1
A29: Exit Scenarios / IRR Calculation
A31: Scenario | B31: Exit Value | C31: VC Ownership | D31: Gain | E31: Net Gain | F31: ROI | G31: IRR | H31: Proabality | I31: Probability Gain Analysis
A32: Base Scenario | B32: 120000000 | C32: 0.125 | D32: =Tableau610[[#This Row],[Exit Value]]*Tableau610[[#This Row],[VC Ownership]] -> 15000000 | E32: =Tableau610[[#This Row],[Gain]]-Inputs!$H$3 -> 12000000 | F32: =(Tableau610[[#This Row],[Gain]]-Inputs!$H$3)/Inputs!$H$3 -> 4 | G32: =((Tableau610[[#This Row],[Gain]]/Inputs!$H$3)^(1/7))-1 -> 0.25849895 | H32: 0.2 | I32: =Tableau610[[#This Row],[Gain]]*Tableau610[[#This Row],[Proabality ]] -> 3000000
A33: Pessimistic | B33: 45000000 | C33: 0.125 | D33: =Tableau610[[#This Row],[Exit Value]]*Tableau610[[#This Row],[VC Ownership]] -> 5625000 | E33: =Tableau610[[#This Row],[Gain]]-Inputs!$H$3 -> 2625000 | F33: =(Tableau610[[#This Row],[Gain]]-Inputs!$H$3)/Inputs!$H$3 -> 0.875 | G33: =((Tableau610[[#This Row],[Gain]]/Inputs!$H$3)^(1/7))-1 -> 0.093956824 | H33: 0.55 | I33: =Tableau610[[#This Row],[Gain]]*Tableau610[[#This Row],[Proabality ]] -> 3093750
A34: Optimistic | B34: 300000000 | C34: 0.125 | D34: =Tableau610[[#This Row],[Exit Value]]*Tableau610[[#This Row],[VC Ownership]] -> 37500000 | E34: =Tableau610[[#This Row],[Gain]]-Inputs!$H$3 -> 34500000 | F34: =(Tableau610[[#This Row],[Gain]]-Inputs!$H$3)/Inputs!$H$3 -> 11.5 | G34: =((Tableau610[[#This Row],[Gain]]/Inputs!$H$3)^(1/7))-1 -> 0.4345029 | H34: 0.25 | I34: =Tableau610[[#This Row],[Gain]]*Tableau610[[#This Row],[Proabality ]] -> 9375000
I35: =SUM(Tableau610[Probability Gain Analysis]) -> 15468750
A36: Growth Rate
A38: Month | B38: Amount | C38: MoM evolution | D38: MoM %
A39: 1 | B39: 21000 | C39: =21000-17500 -> 3500 | D39: =(Tableau111[[#This Row],[Amount]]-17500)/17500 -> 0.2
A40: 2 | B40: 26000 | C40: =Tableau111[[#This Row],[Amount]]-B39 -> 5000 | D40: =(Tableau111[[#This Row],[Amount]]-B39)/B39 -> 0.23809524
A41: 3 | B41: 31000 | C41: =Tableau111[[#This Row],[Amount]]-B40 -> 5000 | D41: =(Tableau111[[#This Row],[Amount]]-B40)/B40 -> 0.19230769
A42: 4 | B42: 35000 | C42: =Tableau111[[#This Row],[Amount]]-B41 -> 4000 | D42: =(Tableau111[[#This Row],[Amount]]-B41)/B41 -> 0.12903226
A43: 5 | B43: 43000 | C43: =Tableau111[[#This Row],[Amount]]-B42 -> 8000 | D43: =(Tableau111[[#This Row],[Amount]]-B42)/B42 -> 0.22857143
A44: 6 | B44: 50000 | C44: =Tableau111[[#This Row],[Amount]]-B43 -> 7000 | D44: =(Tableau111[[#This Row],[Amount]]-B43)/B43 -> 0.1627907
A45: 7 | B45: 62000 | C45: =Tableau111[[#This Row],[Amount]]-B44 -> 12000 | D45: =(Tableau111[[#This Row],[Amount]]-B44)/B44 -> 0.24
A46: 8 | B46: 71000 | C46: =Tableau111[[#This Row],[Amount]]-B45 -> 9000 | D46: =(Tableau111[[#This Row],[Amount]]-B45)/B45 -> 0.14516129
A47: 9 | B47: 88000 | C47: =Tableau111[[#This Row],[Amount]]-B46 -> 17000 | D47: =(Tableau111[[#This Row],[Amount]]-B46)/B46 -> 0.23943662
...

Sheet Graphics
